<?xml version="1.0" ?>

<!-- Robot description-->
<robot name="bcn3d_moveo">

  <!-- ================================== -->
  <!-- MANIPULATOR -->
  <!-- ================================== -->

  <!-- Link_0 (Base) -->  
  <link name="Link_0">

    <collision>
      <origin rpy="0 0 0" xyz="0 0 0"/>
      <geometry>
        <mesh filename="package://bcn3d_moveo_description/meshes/Base.STL" scale="0.000001 0.000001 0.000001"/>
      </geometry>
    </collision>

    <visual>
      <origin rpy="0 0 0" xyz="0 0 0"/>
      <geometry>
        <mesh filename="package://bcn3d_moveo_description/meshes/Base.STL" scale="0.000001 0.000001 0.000001"/>
      </geometry>
      <material name="Orange">
        <color rgba="0.945 0.353 0.133 1.0"/>
      </material>
    </visual>

  </link>

  <link name="Link_1">

    <visual>
      <origin rpy="0 0 0" xyz="0 0 0"/>
      <geometry>
        <mesh filename="package://bcn3d_moveo_description/meshes/column.STL" scale="0.001 0.001 0.001"/>
      </geometry>
      <material name="Orange">
        <color rgba="0.945 0.353 0.133 1.0"/>
      </material>
    </visual>

    <collision>
      <origin rpy="0 0 0" xyz="0 0 0"/>
      <geometry>
        <mesh filename="package://bcn3d_moveo_description/meshes/column.STL" scale="0.001 0.001 0.001"/>
      </geometry>
    </collision>

  </link>

  <joint name="Joint_1" type="revolute">

    <origin rpy="3.14 0 4.71239" xyz="0 0 0.008"/>
    <parent link="Link_0"/>
    <child link="Link_1"/>
    <axis xyz="0 0 1" />
    <limit lower="-1.74532925199" upper="1.745329251997" effort="5.0" velocity="1.0" />

  </joint>

  <link name="Link_2">

    <visual>
      <origin rpy="0 0 0" xyz="0 0 0"/>
      <geometry>
        <mesh filename="package://bcn3d_moveo_description/meshes/Link_2.STL"/>
      </geometry>
      <material name="Orange">
        <color rgba="0.945 0.353 0.133 1.0"/>
      </material>
    </visual>

    <collision>
      <origin rpy="0 0 0" xyz="0 0 0"/>
      <geometry>
        <mesh filename="package://bcn3d_moveo_description/meshes/Link_2.STL"/>
      </geometry>
    </collision>

  </link>

  <joint name="Joint_2" type="revolute">
    <origin rpy="0 0 3.94" xyz="0 0 -0.1655"/>
    <parent link="Link_1"/>
    <child link="Link_2"/>
    <axis xyz="0 -1 0" />
    <limit lower="-1" upper="1" effort="5.0" velocity="1.0" />
  </joint>

  <link name="Link_3">

    <visual>
      <origin rpy="0 0 0" xyz="0 0 0"/>
      <geometry>
        <mesh filename="package://bcn3d_moveo_description/meshes/Link_3.STL"/>
      </geometry>
      <material name="Orange">
        <color rgba="0.945 0.353 0.133 1.0"/>
      </material>
    </visual>

    <collision>
      <origin rpy="0 0 0" xyz="0 0 0"/>
      <geometry>
        <mesh filename="package://bcn3d_moveo_description/meshes/Link_3.STL"/>
      </geometry>
    </collision>

  </link>

  <joint name="Joint_3" type="revolute">
    <origin rpy="-3.1416 0 -3.1416" xyz="0 0 -0.22112"/>
    <parent link="Link_2"/>
    <child link="Link_3"/>
    <axis xyz="0 -1 0" />
    <limit lower="0" upper="3.14" effort="5.0" velocity="1.0" />
  </joint>

  <link name="Link_4">

    <visual>
      <origin rpy="0 0 0" xyz="0 0 0"/>
      <geometry>
        <mesh filename="package://bcn3d_moveo_description/meshes/Link_4.STL"/>
      </geometry>
      <material name="Orange">
        <color rgba="0.945 0.353 0.133 1.0"/>
      </material>
    </visual>

    <collision>
      <origin rpy="0 0 0" xyz="0 0 0"/>
      <geometry>
        <mesh filename="package://bcn3d_moveo_description/meshes/Link_4.STL"/>
      </geometry>
    </collision>

  </link>

  <joint name="Joint_4" type="revolute">
    <origin rpy="3.1416 -1.57 1.5708" xyz="0.16988 -0.00099213 0"/>
    <parent link="Link_3"/>
    <child link="Link_4"/>
    <axis xyz="0 -1 0" />
    <limit lower="-1.57" upper="1.57" effort="5.0" velocity="1.0" />
  </joint>

  <link name="Hand">

    <visual>
      <origin rpy="0 0 0" xyz="0 0 0"/>
      <geometry>
        <mesh filename="package://bcn3d_moveo_description/meshes/Link_5.STL"/>
      </geometry>
      <material name="Orange">
        <color rgba="0.945 0.353 0.133 1.0"/>
      </material>
    </visual>

    <collision>
      <origin rpy="0 0 0" xyz="0 0 0"/>
      <geometry>
        <mesh filename="package://bcn3d_moveo_description/meshes/Link_5.STL"/>
      </geometry>
    </collision>

  </link>

  <joint name="Joint_5" type="revolute">
    <origin rpy="-1.57 0 -0.906941" xyz="-0.0021346 0.053041 0.0016936"/>
    <parent link="Link_4"/>
    <child link="Hand"/>
    <axis xyz="0 1 0" />
    <limit lower="-0.663225" upper="0.663225" effort="5.0" velocity="1.0" />
  </joint>

  <link name="Gripper_Servo_Gear">
    <visual>
      <origin rpy="0 0 0" xyz="0 0 0"/>
      <geometry>
        <mesh filename="package://bcn3d_moveo_description/meshes/Gripper_Servo_Gear.STL"/>
      </geometry>
      <material name="Orange">
        <color rgba="0.945 0.353 0.133 1.0"/>
      </material>
    </visual>
    <collision>
      <origin rpy="0 0 0" xyz="0 0 0"/>
      <geometry>
        <mesh filename="package://bcn3d_moveo_description/meshes/Gripper_Servo_Gear.STL"/>
      </geometry>
    </collision>
  </link>

  <joint name="Gripper_Servo_Gear_Joint" type="revolute">
    <origin rpy="0.9321 0.032705 -1.5268" xyz="-0.05013 0.01413 0.041516"/>
    <parent link="Hand"/>
    <child link="Gripper_Servo_Gear"/>
    <axis xyz="0 1 0" />
    <limit lower="0" upper="1.39626" effort="5.0" velocity="10.0" />
  </joint>

  <link name="Tip_Gripper_Servo">
    <visual>
      <origin rpy="0 0 0" xyz="0 0 0"/>
      <geometry>
        <mesh filename="package://bcn3d_moveo_description/meshes/Tip_Gripper_Servo.STL"/>
      </geometry>
      <material name="Orange">
        <color rgba="0.945 0.353 0.133 1.0"/>
      </material>
    </visual>
    <collision>
      <origin rpy="0 0 0" xyz="0 0 0"/>
      <geometry>
        <mesh filename="package://bcn3d_moveo_description/meshes/Tip_Gripper_Servo.STL"/>
      </geometry>
    </collision>
  </link>

  <joint name="Tip_Gripper_Servo_Joint" type="revolute">
    <origin rpy="-3.1416 -1.5569 -2.0392E-12" xyz="-0.039906 -0.004 -0.0027473"/>
    <parent link="Gripper_Servo_Gear"/>
    <child link="Tip_Gripper_Servo"/>
    <axis xyz="0 1 0" />
    <limit lower="0" upper="1.39626" effort="5.0" velocity="10.0" />
  </joint>

  <link name="Gripper_Idol_Gear">

    <visual>
      <origin rpy="0 0 0" xyz="0 0 0"/>
      <geometry>
        <mesh filename="package://bcn3d_moveo_description/meshes/Gripper_Idol_Gear.STL"/>
      </geometry>
      <material name="Orange">
        <color rgba="0.945 0.353 0.133 1.0"/>
      </material>
    </visual>

    <collision>
      <origin rpy="0 0 0" xyz="0 0 0"/>
      <geometry>
        <mesh filename="package://bcn3d_moveo_description/meshes/Gripper_Idol_Gear.STL"/>
      </geometry>
    </collision>

  </link>

  <joint name="Gripper_Idol_Gear_Joint" type="revolute">
    <origin rpy="2.2091 -0.040996 1.626" xyz="-0.052696 -0.01387 0.038065"/>
    <parent link="Hand"/>
    <child link="Gripper_Idol_Gear"/>
    <axis xyz="0 1 0" />
    <limit lower="-1.39626" upper="1.39626" effort="5.0" velocity="10.0" />
  </joint>

  <link name="Tip_Gripper_Idol">

    <visual>
      <origin rpy="0 0 0" xyz="0 0 0"/>
      <geometry>
        <mesh filename="package://bcn3d_moveo_description/meshes/Tip_Gripper_Idol.STL"/>
      </geometry>
      <material name="Orange">
        <color rgba="0.945 0.353 0.133 1.0"/>
      </material>
    </visual>

    <collision>
      <origin rpy="0 0 0" xyz="0 0 0"/>
      <geometry>
        <mesh filename="package://bcn3d_moveo_description/meshes/Tip_Gripper_Idol.STL"/>
      </geometry>
    </collision>

  </link>

  <joint name="Tip_Gripper_Idol_Joint" type="revolute">
    <origin rpy="3.1416 0.5236 3.1416" xyz="-0.039906 -0.000125 -0.0027473"/>
    <parent link="Gripper_Idol_Gear"/>
    <child link="Tip_Gripper_Idol"/>
    <axis xyz="0 1 0" />
    <limit lower="-1.39626" upper="1.39626" effort="5.0" velocity="10.0" />
  </joint>

  <link name="Pivot_Arm_Gripper_Servo">

    <visual>
      <origin rpy="0 0 0" xyz="0 0 0"/>
      <geometry>
        <mesh filename="package://bcn3d_moveo_description/meshes/Pivot_Arm_Gripper_Servo.STL"/>
      </geometry>
      <material name="Orange">
        <color rgba="0.945 0.353 0.133 1.0"/>
      </material>
    </visual>

    <collision>
      <origin rpy="0 0 0" xyz="0 0 0"/>
      <geometry>
        <mesh filename="package://bcn3d_moveo_description/meshes/Pivot_Arm_Gripper_Servo.STL"/>
      </geometry>
    </collision>

  </link>

  <joint name="Pivot_Arm_Gripper_Servo_Joint" type="revolute">
    <origin rpy="0.93142 -0.0083007 -1.582" xyz="-0.068745 0.00713 0.05"/>
    <parent link="Hand"/>
    <child link="Pivot_Arm_Gripper_Servo"/>
    <axis xyz="0 1 0" />
    <limit lower="-1.39626" upper="1.39626" effort="5.0" velocity="10.0" />
  </joint>

  <link name="Pivot_Arm_Gripper_Idol">

    <visual>
      <origin rpy="0 0 0" xyz="0 0 0"/>
      <geometry>
        <mesh filename="package://bcn3d_moveo_description/meshes/Pivot_Arm_Gripper_Idol.STL"/>
      </geometry>
      <material name="Orange">
        <color rgba="0.945 0.353 0.133 1.0"/>
      </material>
    </visual>

    <collision>
      <origin rpy="0 0 0" xyz="0 0 0"/>
      <geometry>
        <mesh filename="package://bcn3d_moveo_description/meshes/Pivot_Arm_Gripper_Idol.STL"/>
      </geometry>
    </collision>

  </link>

  <joint name="Pivot_Arm_Gripper_Idol_Joint" type="revolute">
    <origin rpy="0.93138 1.7645E-12 -1.5708" xyz="-0.06867 -0.00687 0.0501"/>
    <parent link="Hand"/>
    <child link="Pivot_Arm_Gripper_Idol"/>
    <axis xyz="0 1 0" />
    <limit lower="-1.39626" upper="1.39626" effort="5.0" velocity="10.0" />
  </joint>

</robot>